<?xml version="1.0" ?>
<!-- =================================================================================== -->
<!-- |    This document was autogenerated by xacro from px100.urdf.xacro               | -->
<!-- |    EDITING THIS FILE BY HAND IS NOT RECOMMENDED                                 | -->
<!-- =================================================================================== -->
<robot name="px100">
  <material name="interbotix_black">
    <texture filename="package://interbotix_xsarm_descriptions/meshes/interbotix_black.png"/>
  </material>
  <!-- use_world_frame -->
  <link name="base_link">
    <visual>
      <origin rpy="0 0 1.5707963267948966" xyz="0 0 0"/>
      <geometry>
        <mesh filename="package://interbotix_xsarm_descriptions/meshes/px100_meshes/base.stl" scale="0.001 0.001 0.001"/>
      </geometry>
      <material name="interbotix_black"/>
    </visual>
    <collision>
      <origin rpy="0 0 1.5707963267948966" xyz="0 0 0"/>
      <geometry>
        <mesh filename="package://interbotix_xsarm_descriptions/meshes/px100_meshes/base.stl" scale="0.001 0.001 0.001"/>
      </geometry>
    </collision>
    <inertial>
      <origin rpy="0 0 1.5707963267948966" xyz="-0.0332053000 0.0008915770 0.0211913000"/>
      <mass value="0.395887"/>
      <inertia ixx="0.0010650000" ixy="-0.0000130300" ixz="0.0000018614" iyy="0.0003332000" iyz="0.0000409200" izz="0.0012080000"/>
    </inertial>
  </link>
  <joint name="waist" type="revolute">
    <axis xyz="0 0 1"/>
    <limit effort="1" lower="-3.141582653589793" upper="3.141582653589793" velocity="3.141592653589793"/>
    <origin rpy="0 0 0" xyz="0 0 0.05085"/>
    <parent link="base_link"/>
    <child link="shoulder_link"/>
    <dynamics damping="0.1" friction="0.1"/>
  </joint>
  <link name="shoulder_link">
    <visual>
      <origin rpy="0 0 1.5707963267948966" xyz="0 0 -0.0022"/>
      <geometry>
        <mesh filename="package://interbotix_xsarm_descriptions/meshes/px100_meshes/shoulder.stl" scale="0.001 0.001 0.001"/>
      </geometry>
      <material name="interbotix_black"/>
    </visual>
    <collision>
      <origin rpy="0 0 1.5707963267948966" xyz="0 0 -0.0022"/>
      <geometry>
        <mesh filename="package://interbotix_xsarm_descriptions/meshes/px100_meshes/shoulder.stl" scale="0.001 0.001 0.001"/>
      </geometry>
    </collision>
    <inertial>
      <origin rpy="0 0 1.5707963267948966" xyz="0.0000111169 -0.0003605640 0.0284598000"/>
      <mass value="0.072587"/>
      <inertia ixx="0.0000231000" ixy="0.0000000003" ixz="0.0000001606" iyy="0.0000253500" iyz="-0.0000000206" izz="0.0000144200"/>
    </inertial>
  </link>
  <joint name="shoulder" type="revolute">
    <axis xyz="0 1 0"/>
    <limit effort="2" lower="-1.9373154697137058" upper="1.8675022996339325" velocity="3.141592653589793"/>
    <origin rpy="0 0 0" xyz="0 0 0.04225"/>
    <parent link="shoulder_link"/>
    <child link="upper_arm_link"/>
    <dynamics damping="0.1" friction="0.1"/>
  </joint>
  <link name="upper_arm_link">
    <visual>
      <origin rpy="0 0 1.5707963267948966" xyz="0 0 0"/>
      <geometry>
        <mesh filename="package://interbotix_xsarm_descriptions/meshes/px100_meshes/upper_arm.stl" scale="0.001 0.001 0.001"/>
      </geometry>
      <material name="interbotix_black"/>
    </visual>
    <collision>
      <origin rpy="0 0 1.5707963267948966" xyz="0 0 0"/>
      <geometry>
        <mesh filename="package://interbotix_xsarm_descriptions/meshes/px100_meshes/upper_arm.stl" scale="0.001 0.001 0.001"/>
      </geometry>
    </collision>
    <inertial>
      <origin rpy="0 0 1.5707963267948966" xyz="0.0161976963 -0.0002929352 0.0877230000"/>
      <mass value="0.082923"/>
      <inertia ixx="0.0000800600" ixy="-0.0000002144" ixz="0.0000002982" iyy="0.0000745900" iyz="0.0000165700" izz="0.0000368500"/>
    </inertial>
  </link>
  <joint name="elbow" type="revolute">
    <axis xyz="0 1 0"/>
    <limit effort="2" lower="-2.111848394913139" upper="1.6057029118347832" velocity="3.141592653589793"/>
    <origin rpy="0 0 0" xyz="0.035 0 0.1"/>
    <parent link="upper_arm_link"/>
    <child link="forearm_link"/>
    <dynamics damping="0.1" friction="0.1"/>
  </joint>
  <link name="forearm_link">
    <visual>
      <origin rpy="0 0 1.5707963267948966" xyz="0 0 0"/>
      <geometry>
        <mesh filename="package://interbotix_xsarm_descriptions/meshes/px100_meshes/forearm.stl" scale="0.001 0.001 0.001"/>
      </geometry>
      <material name="interbotix_black"/>
    </visual>
    <collision>
      <origin rpy="0 0 1.5707963267948966" xyz="0 0 0"/>
      <geometry>
        <mesh filename="package://interbotix_xsarm_descriptions/meshes/px100_meshes/forearm.stl" scale="0.001 0.001 0.001"/>
      </geometry>
    </collision>
    <inertial>
      <origin rpy="0 0 1.5707963267948966" xyz="0.0773720000 -0.0003324882 0.0000000000"/>
      <mass value="0.073058"/>
      <inertia ixx="0.0000533800" ixy="-0.0000003073" ixz="0.0000000000" iyy="0.0000165300" iyz="0.0000000000" izz="0.0000603500"/>
    </inertial>
  </link>
  <!-- Include the gripper if used -->
  <joint name="wrist_angle" type="revolute">
    <axis xyz="0 1 0"/>
    <limit effort="1" lower="-1.7453292519943295" upper="2.1467549799530254" velocity="3.141592653589793"/>
    <origin rpy="0 0 0" xyz="0.1 0 0"/>
    <parent link="forearm_link"/>
    <child link="gripper_link"/>
    <dynamics damping="0.1" friction="0.1"/>
  </joint>
  <link name="gripper_link">
    <visual>
      <origin rpy="0 0 1.5707963267948966" xyz="0 0 0"/>
      <geometry>
        <mesh filename="package://interbotix_xsarm_descriptions/meshes/px100_meshes/gripper.stl" scale="0.001 0.001 0.001"/>
      </geometry>
      <material name="interbotix_black"/>
    </visual>
    <collision>
      <origin rpy="0 0 1.5707963267948966" xyz="0 0 0"/>
      <geometry>
        <mesh filename="package://interbotix_xsarm_descriptions/meshes/px100_meshes/gripper.stl" scale="0.001 0.001 0.001"/>
      </geometry>
    </collision>
    <inertial>
      <origin rpy="0 0 1.5707963267948966" xyz="0.0446910000 0.0000000000 0.0113540000"/>
      <mass value="0.069929"/>
      <inertia ixx="0.0000226800" ixy="0.0000000000" ixz="0.0000000000" iyy="0.0000204400" iyz="0.0000008485" izz="0.0000197400"/>
    </inertial>
  </link>
  <joint name="ee_arm" type="fixed">
    <axis xyz="1 0 0"/>
    <origin rpy="0 0 0" xyz="0.063 0 0"/>
    <parent link="gripper_link"/>
    <child link="ee_arm_link"/>
  </joint>
  <link name="ee_arm_link">
    <inertial>
      <mass value="0.001"/>
      <inertia ixx="0.001" ixy="0" ixz="0" iyy="0.001" iyz="0" izz="0.001"/>
    </inertial>
  </link>
  <joint name="gripper" type="continuous">
    <axis xyz="1 0 0"/>
    <limit effort="1" velocity="3.141592653589793"/>
    <origin rpy="0 0 0" xyz="0.0055 0 0"/>
    <parent link="ee_arm_link"/>
    <child link="gripper_prop_link"/>
    <dynamics damping="0.1" friction="0.1"/>
  </joint>
  <link name="gripper_prop_link">
    <visual>
      <origin rpy="0 0 1.5707963267948966" xyz="-0.0685 0 0"/>
      <geometry>
        <mesh filename="package://interbotix_xsarm_descriptions/meshes/px100_meshes/gripper_prop.stl" scale="0.001 0.001 0.001"/>
      </geometry>
      <material name="interbotix_black"/>
    </visual>
    <collision>
      <origin rpy="0 0 1.5707963267948966" xyz="-0.0685 0 0"/>
      <geometry>
        <mesh filename="package://interbotix_xsarm_descriptions/meshes/px100_meshes/gripper_prop.stl" scale="0.001 0.001 0.001"/>
      </geometry>
    </collision>
    <inertial>
      <origin rpy="0 0 1.5707963267948966" xyz="0.0008460000 -0.0000019330 0.0000420000"/>
      <mass value="0.00434"/>
      <inertia ixx="0.0000005923" ixy="0.0000000000" ixz="0.0000003195" iyy="0.0000011156" iyz="-0.0000000004" izz="0.0000005743"/>
    </inertial>
  </link>
  <!-- If the AR tag is being used, then add the AR tag mount -->
  <!-- show_ar_tag -->
  <!-- If the gripper bar is being used, then also add the gripper bar -->
  <joint name="gripper_bar" type="fixed">
    <axis xyz="1 0 0"/>
    <origin rpy="0 0 0" xyz="0 0 0"/>
    <parent link="ee_arm_link"/>
    <child link="gripper_bar_link"/>
  </joint>
  <link name="gripper_bar_link">
    <visual>
      <origin rpy="0 0 1.5707963267948966" xyz="-0.063 0 0"/>
      <geometry>
        <mesh filename="package://interbotix_xsarm_descriptions/meshes/px100_meshes/gripper_bar.stl" scale="0.001 0.001 0.001"/>
      </geometry>
      <material name="interbotix_black"/>
    </visual>
    <collision>
      <origin rpy="0 0 1.5707963267948966" xyz="-0.063 0 0"/>
      <geometry>
        <mesh filename="package://interbotix_xsarm_descriptions/meshes/px100_meshes/gripper_bar.stl" scale="0.001 0.001 0.001"/>
      </geometry>
    </collision>
    <inertial>
      <origin rpy="0 0 1.5707963267948966" xyz="0.0096870000 0.0000005660 0.0049620000"/>
      <mass value="0.034199"/>
      <inertia ixx="0.0000074125" ixy="-0.0000000008" ixz="-0.0000000006" iyy="0.0000284300" iyz="-0.0000013889" izz="0.0000286000"/>
    </inertial>
  </link>
  <joint name="ee_bar" type="fixed">
    <axis xyz="1 0 0"/>
    <origin rpy="0 0 0" xyz="0.023 0 0"/>
    <parent link="gripper_bar_link"/>
    <child link="fingers_link"/>
  </joint>
  <link name="fingers_link">
    <inertial>
      <mass value="0.001"/>
      <inertia ixx="0.001" ixy="0" ixz="0" iyy="0.001" iyz="0" izz="0.001"/>
    </inertial>
  </link>
  <!-- If the gripper fingers are being used, add those as well -->
  <joint name="left_finger" type="prismatic">
    <axis xyz="0 1 0"/>
    <limit effort="5" lower="0.015" upper="0.037" velocity="1"/>
    <origin rpy="0 0 0" xyz="0 0 0"/>
    <parent link="fingers_link"/>
    <child link="left_finger_link"/>
    <dynamics damping="0.1" friction="0.1"/>
  </joint>
  <link name="left_finger_link">
    <visual>
      <origin rpy="3.141592653589793 3.141592653589793 0" xyz="0 0.005 0"/>
      <geometry>
        <mesh filename="package://interbotix_xsarm_descriptions/meshes/px100_meshes/gripper_finger.stl" scale="0.001 0.001 0.001"/>
      </geometry>
      <material name="interbotix_black"/>
    </visual>
    <collision>
      <origin rpy="3.141592653589793 3.141592653589793 0" xyz="0 0.005 0"/>
      <geometry>
        <mesh filename="package://interbotix_xsarm_descriptions/meshes/px100_meshes/gripper_finger.stl" scale="0.001 0.001 0.001"/>
      </geometry>
    </collision>
    <inertial>
      <origin rpy="3.141592653589793 3.141592653589793 1.5707963267948966" xyz="0.0138160000 0.0000000000 0.0000000000"/>
      <mass value="0.016246"/>
      <inertia ixx="0.0000047310" ixy="-0.0000004560" ixz="0.0000000000" iyy="0.0000015506" iyz="0.0000000000" izz="0.0000037467"/>
    </inertial>
  </link>
  <joint name="right_finger" type="prismatic">
    <axis xyz="0 1 0"/>
    <limit effort="5" lower="-0.037" upper="-0.015" velocity="1"/>
    <origin rpy="0 0 0" xyz="0 0 0"/>
    <parent link="fingers_link"/>
    <child link="right_finger_link"/>
    <dynamics damping="0.1" friction="0.1"/>
    <mimic joint="left_finger" multiplier="-1" offset="0"/>
  </joint>
  <link name="right_finger_link">
    <visual>
      <origin rpy="0 3.141592653589793 0" xyz="0 -0.005 0"/>
      <geometry>
        <mesh filename="package://interbotix_xsarm_descriptions/meshes/px100_meshes/gripper_finger.stl" scale="0.001 0.001 0.001"/>
      </geometry>
      <material name="interbotix_black"/>
    </visual>
    <collision>
      <origin rpy="0 3.141592653589793 0" xyz="0 -0.005 0"/>
      <geometry>
        <mesh filename="package://interbotix_xsarm_descriptions/meshes/px100_meshes/gripper_finger.stl" scale="0.001 0.001 0.001"/>
      </geometry>
    </collision>
    <inertial>
      <origin rpy="0 3.141592653589793 1.5707963267948966" xyz="0.0138160000 0.0000000000  0.0000000000"/>
      <mass value="0.016246"/>
      <inertia ixx="0.0000047310" ixy="0.0000004560" ixz="0.0000000000" iyy="0.0000015506" iyz="0.0000000000" izz="0.0000037467"/>
    </inertial>
  </link>
  <joint name="ee_gripper" type="fixed">
    <axis xyz="1 0 0"/>
    <origin rpy="0 0 0" xyz="0.027575 0 0"/>
    <parent link="fingers_link"/>
    <child link="ee_gripper_link"/>
  </joint>
  <link name="ee_gripper_link">
    <inertial>
      <mass value="0.001"/>
      <inertia ixx="0.001" ixy="0" ixz="0" iyy="0.001" iyz="0" izz="0.001"/>
    </inertial>
  </link>
  <!-- show_gripper_fingers -->
  <!-- show_gripper_bar -->
  <!-- use_gripper -->
  <ros2_control name="XSHardwareInterface" type="system">
    <hardware>
      <plugin>interbotix_xs_ros_control/XSHardwareInterface</plugin>
      <param name="loop_hz">10</param>
      <param name="group_name">arm</param>
      <param name="gripper_name">gripper</param>
      <param name="joint_states_topic">joint_states</param>
    </hardware>
    <joint name="waist">
      <command_interface name="position">
        <param name="min">&quot;-3.141582653589793&quot;</param>
        <param name="max">&quot;3.141582653589793&quot;</param>
      </command_interface>
      <state_interface name="position"/>
    </joint>
    <joint name="shoulder">
      <command_interface name="position">
        <param name="min">&quot;-1.9373154697137058&quot;</param>
        <param name="max">&quot;1.8675022996339325&quot;</param>
      </command_interface>
      <state_interface name="position"/>
    </joint>
    <joint name="elbow">
      <command_interface name="position">
        <param name="min">&quot;-2.111848394913139&quot;</param>
        <param name="max">&quot;1.6057029118347832&quot;</param>
      </command_interface>
      <state_interface name="position"/>
    </joint>
    <joint name="wrist_angle">
      <command_interface name="position">
        <param name="min">&quot;-1.7453292519943295&quot;</param>
        <param name="max">&quot;2.1467549799530254&quot;</param>
      </command_interface>
      <state_interface name="position"/>
    </joint>
    <joint name="left_finger">
      <command_interface name="position">
        <param name="min">&quot;0.015&quot;</param>
        <param name="max">&quot;-0.015&quot;</param>
      </command_interface>
      <state_interface name="position"/>
    </joint>
  </ros2_control>
</robot>
